<?xml version="1.0" encoding="utf-8"?>
<!-- =================================================================================== -->
<!-- |    This document was autogenerated by xacro from box.urdf.xacro                 | -->
<!-- |    EDITING THIS FILE BY HAND IS NOT RECOMMENDED                                 | -->
<!-- =================================================================================== -->
<robot name="box">
  <!-- Base link -->
  <link name="obj_base">
    <origin xyz="0 0 0"/>
  </link>
  <joint name="base_joint" type="revolute">
    <limit effort="15" lower="-0.47" upper="0.47" velocity="7"/>
    <parent link="obj_base"/>
    <child link="object_link"/>
    <origin xyz="0 0 0"/>
  </joint>
  <!-- object link -->
  <link name="object_link">
    <visual>
      <geometry>
        <box size="0.04 0.14 0.03"/>
      </geometry>
      <origin rpy="0 0 0" xyz="0.1 -0.02 0.105"/>
      <material name="red">
        <color rgba="0.5 0.2 0.2 0.7"/>
      </material>
    </visual>
    <collision>
      <geometry>
        <box size="0.04 0.14 0.03"/>
      </geometry>
    </collision>
  </link>
</robot>
