<?xml version="1.0" encoding="utf-8"?>
<!-- =================================================================================== -->
<!-- |    This document was autogenerated by xacro from cylinder.urdf.xacro            | -->
<!-- |    EDITING THIS FILE BY HAND IS NOT RECOMMENDED                                 | -->
<!-- =================================================================================== -->
<robot name="cylinder">
  <!-- Base link -->
  <link name="obj_base">
    <origin xyz="0 0 0"/>
  </link>
  <joint name="base_joint" type="revolute">
    <limit effort="15" lower="-0.47" upper="0.47" velocity="7"/>
    <parent link="obj_base"/>
    <child link="object_link"/>
    <origin xyz="0 0 0"/>
  </joint>
  <!-- object link -->
  <link name="object_link">
    <visual>
      <geometry>
        <cylinder length="0.12" radius="0.025"/>
      </geometry>
      <origin rpy="1.5707963268 0 0" xyz="0.1 -0.02 0.11"/>
      <material name="green">
        <color rgba="0.2 0.5 0.2 0.7"/>
      </material>
    </visual>
    <collision>
      <geometry>
        <cylinder length="0.12" radius="0.025"/>
      </geometry>
    </collision>
  </link>
</robot>
