<?xml version="1.0"?>
<robot xmlns:xacro="http://www.ros.org/wiki/xacro" name="sphere">
    <xacro:property name="PI" value="3.14159265359" />
    <xacro:property name="s_radius" value="0.05" />
    <xacro:property name="opacity" value="0.7" />
    <xacro:property name="obj_x" value="0.105" />
    <xacro:property name="obj_y" value="-0.03" />
    <xacro:property name="obj_z" value="0.11" />
    <!-- Base link -->
    <link name="obj_base">
        <origin xyz="0 0 0"/>
    </link>
    <joint name="base_joint" type="revolute">
        <limit effort="15" lower="-0.47" upper="0.47" velocity="7"/>
        <parent link="obj_base"/>
        <child link="object_link"/>
        <origin xyz="0 0 0"/>
    </joint>
    <!-- object link -->
    <link name="object_link">
        <visual>
            <geometry>
                <sphere radius="${s_radius}"/>
            </geometry>
            <origin rpy="${PI/2} 0 0" xyz="${obj_x} ${obj_y} ${obj_z}"/>
            <material name="blue">
                <color rgba="0.1 0.1 0.7 ${opacity}"/>
            </material>
        </visual>
        <collision>
            <geometry>
                <sphere radius="${s_radius}"/>
            </geometry>
        </collision>
    </link>
</robot>